{"status":"OK","result":{"originalLocale":"ru","allowViewHistory":true,"creationTimeSeconds":1488114413,"rating":13,"authorHandle":"LLI_E_P_JI_O_K","modificationTimeSeconds":1488114413,"id":50683,"title":"\u003cp\u003eStrange behaviour for vector\u0026lt;\u0026gt; in GNU C++11\u003c/p\u003e","locale":"ru","content":"\u003cdiv class\u003d\"ttypography\"\u003e\u003cp\u003eHello, guys!\u003c/p\u003e\u003cp\u003eToday in Codeforces round 402 (Div 2) I tried to challenge \u003ca href\u003d\"//codeforces.com/contest/779/submission/25041987\"\u003ethis solution\u003c/a\u003e with a test:\u003c/p\u003e \u003cpre\u003e5 2\n1 1 1 1 1\n5 5 5 5 5\u003c/pre\u003e\u003cp\u003eSo, as you can see in the code this cycle has no any check for reaching the end of the vector \u0026quot;v\u0026quot;:\u003c/p\u003e \u003cpre\u003e...\nwhile (v[j].first\u0026lt;0||j\u0026lt;r)\n{\nsum1+\u003dv1[v[j].second];\nj++;    \n}\n...\u003c/pre\u003e\u003cp\u003eObviously \u0026quot;j\u0026quot; will be out of the vector for such testcase and we will check whether \u0026quot;v[5].first\u0026lt;0\u0026quot; or not, but no any Runtime Error when trying to get nonexistent element of vector. So, as you can understand, challenge was unsuccessful. Why?\u003c/p\u003e\u003c/div\u003e","tags":["vector","g++","bound overflow","runtime error"]}}